<?xml version="1.0" encoding="UTF-8"?>
<testsuite errors="1" failures="0" file="helloworld_tests.py" name="helloworld_tests.HelloWorldTest-20190409130033" skipped="0" tests="1" time="0.001" timestamp="2019-04-09T13:00:33">
	<testcase classname="helloworld_tests.HelloWorldTest" file="src\unittest\python\helloworld_tests.py" line="8" name="test_should_issue_hello_world_message" time="0.001" timestamp="2019-04-09T13:00:33">
		<error message="'VerifiableInvocation' object has no attribute 'assert_called_with'" type="AttributeError">
<![CDATA[Traceback (most recent call last):
  File "e:\capstone project\pybuilder\src\unittest\python\helloworld_tests.py", line 13, in test_should_issue_hello_world_message
    verify(out).write.assert_called_with("Hello world of Python\n")
AttributeError: 'VerifiableInvocation' object has no attribute 'assert_called_with'
]]>		</error>
		<system-out>
<![CDATA[]]>		</system-out>
		<system-err>
<![CDATA[]]>		</system-err>
	</testcase>
</testsuite>
